<?xml version="1.0" encoding="utf-8"?>
<!-- This URDF was automatically created by SolidWorks to URDF Exporter! Originally created by Stephen Brawner (brawner@gmail.com) 
     Commit Version: 1.5.1-0-g916b5db  Build Version: 1.5.7152.31018
     For more information, please see http://wiki.ros.org/sw_urdf_exporter -->
<robot
  name="ballbot 3.0">
  <link
    name="base_link">
    <inertial>
      <origin
        xyz="0.00034247 -0.34147 0.049723"
        rpy="0 0 0" />
      <mass
        value="11.5" />
      <inertia
        ixx="0.0041015"
        ixy="4.4238E-06"
        ixz="4.0991E-07"
        iyy="0.004503"
        iyz="-1.004E-06"
        izz="0.0077111" />
    </inertial>
    <visual>
      <origin
        xyz="0 0 0"
        rpy="0 0 0" />
      <geometry>
        <mesh
          filename="package://ballbot 3.0/meshes/base_link.STL" />
      </geometry>
      <material
        name="">
        <color
          rgba="0.79216 0.81961 0.93333 1" />
      </material>
    </visual>
    <collision>
      <origin
        xyz="0 0 0"
        rpy="0 0 0" />
      <geometry>
        <mesh
          filename="package://ballbot 3.0/meshes/base_link.STL" />
      </geometry>
    </collision>
  </link>
  <link
    name="omniwheel4">
    <inertial>
      <origin
        xyz="-0.0033504 -0.017313 0.00031354"
        rpy="0 0 0" />
      <mass
        value="0.4" />
      <inertia
        ixx="5.3804E-05"
        ixy="1.7084E-06"
        ixz="-4.8248E-09"
        iyy="7.3424E-05"
        iyz="-1.9402E-07"
        izz="5.3646E-05" />
    </inertial>
    <visual>
      <origin
        xyz="0 0 0"
        rpy="0 0 0" />
      <geometry>
        <mesh
          filename="package://ballbot 3.0/meshes/omniwheel4.STL" />
      </geometry>
      <material
        name="">
        <color
          rgba="1 1 1 1" />
      </material>
    </visual>
    <collision>
      <origin
        xyz="0 0 0"
        rpy="0 0 0" />
      <geometry>
        <mesh
          filename="package://ballbot 3.0/meshes/omniwheel4.STL" />
      </geometry>
    </collision>
  </link>
  <joint
    name="omniwheel4"
    type="continuous">
    <origin
      xyz="-0.11348 -0.34003 -0.052798"
      rpy="1.4806 0.69325 -0.14058" />
    <parent
      link="base_link" />
    <child
      link="omniwheel4" />
    <axis
      xyz="0 1 0" />
  </joint>
  <link
    name="wheel41">
    <inertial>
      <origin
        xyz="7.1848E-06 6.8694E-06 2.982E-06"
        rpy="0 0 0" />
      <mass
        value="0.0023" />
      <inertia
        ixx="2.1874E-07"
        ixy="4.4072E-16"
        ixz="-4.7451E-16"
        iyy="2.4987E-07"
        iyz="1.5924E-18"
        izz="2.4987E-07" />
    </inertial>
    <visual>
      <origin
        xyz="0 0 0"
        rpy="0 0 0" />
      <geometry>
        <mesh
          filename="package://ballbot 3.0/meshes/wheel41.STL" />
      </geometry>
      <material
        name="">
        <color
          rgba="0.79216 0.81961 0.93333 1" />
      </material>
    </visual>
    <collision>
      <origin
        xyz="0 0 0"
        rpy="0 0 0" />
      <geometry>
        <mesh
          filename="package://ballbot 3.0/meshes/wheel41.STL" />
      </geometry>
    </collision>
  </link>
  <joint
    name="wheel41"
    type="continuous">
    <origin
      xyz="0.022594 -0.010412 0.03125"
      rpy="-0.73638 -0.68311 3.0472" />
    <parent
      link="omniwheel4" />
    <child
      link="wheel41" />
    <axis
      xyz="1 0 0" />
  </joint>
  <link
    name="wheel42">
    <inertial>
      <origin
        xyz="3.9928E-06 9.4484E-06 2.0535E-07"
        rpy="0 0 0" />
      <mass
        value="0.0023" />
      <inertia
        ixx="2.1874E-07"
        ixy="-1.571E-14"
        ixz="1.6915E-14"
        iyy="2.4987E-07"
        iyz="2.0581E-15"
        izz="2.4987E-07" />
    </inertial>
    <visual>
      <origin
        xyz="0 0 0"
        rpy="0 0 0" />
      <geometry>
        <mesh
          filename="package://ballbot 3.0/meshes/wheel42.STL" />
      </geometry>
      <material
        name="">
        <color
          rgba="0.79216 0.81961 0.93333 1" />
      </material>
    </visual>
    <collision>
      <origin
        xyz="0 0 0"
        rpy="0 0 0" />
      <geometry>
        <mesh
          filename="package://ballbot 3.0/meshes/wheel42.STL" />
      </geometry>
    </collision>
  </link>
  <joint
    name="wheel42"
    type="continuous">
    <origin
      xyz="0.036556 -0.011848 0.0077631"
      rpy="-0.69867 -1.3811 3.0059" />
    <parent
      link="omniwheel4" />
    <child
      link="wheel42" />
    <axis
      xyz="1 0 0" />
  </joint>
  <link
    name="wheel43">
    <inertial>
      <origin
        xyz="-8.9079E-07 1.0028E-05 -4.1885E-07"
        rpy="0 0 0" />
      <mass
        value="0.0023" />
      <inertia
        ixx="2.1874E-07"
        ixy="-1.8078E-14"
        ixz="1.9464E-14"
        iyy="2.4987E-07"
        iyz="2.2873E-15"
        izz="2.4987E-07" />
    </inertial>
    <visual>
      <origin
        xyz="0 0 0"
        rpy="0 0 0" />
      <geometry>
        <mesh
          filename="package://ballbot 3.0/meshes/wheel43.STL" />
      </geometry>
      <material
        name="">
        <color
          rgba="0.79216 0.81961 0.93333 1" />
      </material>
    </visual>
    <collision>
      <origin
        xyz="0 0 0"
        rpy="0 0 0" />
      <geometry>
        <mesh
          filename="package://ballbot 3.0/meshes/wheel43.STL" />
      </geometry>
    </collision>
  </link>
  <joint
    name="wheel43"
    type="continuous">
    <origin
      xyz="0.032203 -0.011724 -0.01925"
      rpy="2.3738 -1.0621 -0.069915" />
    <parent
      link="omniwheel4" />
    <child
      link="wheel43" />
    <axis
      xyz="1 0 0" />
  </joint>
  <link
    name="wheel44">
    <inertial>
      <origin
        xyz="-5.1771E-06 8.3376E-06 1.4013E-06"
        rpy="0 0 0" />
      <mass
        value="0.0023" />
      <inertia
        ixx="2.1874E-07"
        ixy="2.6295E-15"
        ixz="-2.8311E-15"
        iyy="2.4987E-07"
        iyz="5.4475E-17"
        izz="2.4987E-07" />
    </inertial>
    <visual>
      <origin
        xyz="0 0 0"
        rpy="0 0 0" />
      <geometry>
        <mesh
          filename="package://ballbot 3.0/meshes/wheel44.STL" />
      </geometry>
      <material
        name="">
        <color
          rgba="0.79216 0.81961 0.93333 1" />
      </material>
    </visual>
    <collision>
      <origin
        xyz="0 0 0"
        rpy="0 0 0" />
      <geometry>
        <mesh
          filename="package://ballbot 3.0/meshes/wheel44.STL" />
      </geometry>
    </collision>
  </link>
  <joint
    name="wheel44"
    type="continuous">
    <origin
      xyz="0.011572 -0.010098 -0.037149"
      rpy="2.383 -0.36403 -0.083182" />
    <parent
      link="omniwheel4" />
    <child
      link="wheel44" />
    <axis
      xyz="1 0 0" />
  </joint>
  <link
    name="wheel45">
    <inertial>
      <origin
        xyz="-6.8649E-06 5.1664E-06 4.8157E-06"
        rpy="0 0 0" />
      <mass
        value="0.0023" />
      <inertia
        ixx="2.1874E-07"
        ixy="2.5622E-15"
        ixz="-2.7587E-15"
        iyy="2.4987E-07"
        iyz="4.6069E-17"
        izz="2.4987E-07" />
    </inertial>
    <visual>
      <origin
        xyz="0 0 0"
        rpy="0 0 0" />
      <geometry>
        <mesh
          filename="package://ballbot 3.0/meshes/wheel45.STL" />
      </geometry>
      <material
        name="">
        <color
          rgba="0.79216 0.81961 0.93333 1" />
      </material>
    </visual>
    <collision>
      <origin
        xyz="0 0 0"
        rpy="0 0 0" />
      <geometry>
        <mesh
          filename="package://ballbot 3.0/meshes/wheel45.STL" />
      </geometry>
    </collision>
  </link>
  <joint
    name="wheel45"
    type="continuous">
    <origin
      xyz="-0.015684 -0.0077316 -0.037559"
      rpy="2.3832 0.33407 -0.090021" />
    <parent
      link="omniwheel4" />
    <child
      link="wheel45" />
    <axis
      xyz="1 0 0" />
  </joint>
  <link
    name="wheel46">
    <inertial>
      <origin
        xyz="-5.159E-06 1.9986E-06 8.2263E-06"
        rpy="0 0 0" />
      <mass
        value="0.0023" />
      <inertia
        ixx="2.1874E-07"
        ixy="-1.0069E-14"
        ixz="1.0841E-14"
        iyy="2.4987E-07"
        iyz="9.4571E-16"
        izz="2.4987E-07" />
    </inertial>
    <visual>
      <origin
        xyz="0 0 0"
        rpy="0 0 0" />
      <geometry>
        <mesh
          filename="package://ballbot 3.0/meshes/wheel46.STL" />
      </geometry>
      <material
        name="">
        <color
          rgba="0.79216 0.81961 0.93333 1" />
      </material>
    </visual>
    <collision>
      <origin
        xyz="0 0 0"
        rpy="0 0 0" />
      <geometry>
        <mesh
          filename="package://ballbot 3.0/meshes/wheel46.STL" />
      </geometry>
    </collision>
  </link>
  <joint
    name="wheel46"
    type="continuous">
    <origin
      xyz="-0.036811 -0.0057311 -0.020288"
      rpy="2.3748 1.0321 -0.10248" />
    <parent
      link="omniwheel4" />
    <child
      link="wheel46" />
    <axis
      xyz="1 0 0" />
  </joint>
  <link
    name="wheel47">
    <inertial>
      <origin
        xyz="-8.6463E-07 3.1784E-07 1.0036E-05"
        rpy="0 0 0" />
      <mass
        value="0.0023" />
      <inertia
        ixx="2.1874E-07"
        ixy="-3.5856E-15"
        ixz="3.8606E-15"
        iyy="2.4987E-07"
        iyz="9.9855E-17"
        izz="2.4987E-07" />
    </inertial>
    <visual>
      <origin
        xyz="0 0 0"
        rpy="0 0 0" />
      <geometry>
        <mesh
          filename="package://ballbot 3.0/meshes/wheel47.STL" />
      </geometry>
      <material
        name="">
        <color
          rgba="0.79216 0.81961 0.93333 1" />
      </material>
    </visual>
    <collision>
      <origin
        xyz="0 0 0"
        rpy="0 0 0" />
      <geometry>
        <mesh
          filename="package://ballbot 3.0/meshes/wheel47.STL" />
      </geometry>
    </collision>
  </link>
  <joint
    name="wheel47"
    type="continuous">
    <origin
      xyz="-0.041924 -0.005033 0.0065827"
      rpy="-0.68944 1.411 3.1131" />
    <parent
      link="omniwheel4" />
    <child
      link="wheel47" />
    <axis
      xyz="1 0 0" />
  </joint>
  <link
    name="wheel48">
    <inertial>
      <origin
        xyz="4.0124E-06 9.0927E-07 9.3992E-06"
        rpy="0 0 0" />
      <mass
        value="0.0023" />
      <inertia
        ixx="2.1874E-07"
        ixy="-5.8857E-15"
        ixz="6.337E-15"
        iyy="2.4987E-07"
        iyz="2.185E-16"
        izz="2.4987E-07" />
    </inertial>
    <visual>
      <origin
        xyz="0 0 0"
        rpy="0 0 0" />
      <geometry>
        <mesh
          filename="package://ballbot 3.0/meshes/wheel48.STL" />
      </geometry>
      <material
        name="">
        <color
          rgba="0.79216 0.81961 0.93333 1" />
      </material>
    </visual>
    <collision>
      <origin
        xyz="0 0 0"
        rpy="0 0 0" />
      <geometry>
        <mesh
          filename="package://ballbot 3.0/meshes/wheel48.STL" />
      </geometry>
    </collision>
  </link>
  <joint
    name="wheel48"
    type="continuous">
    <origin
      xyz="-0.028631 -0.0059639 0.03048"
      rpy="-0.73607 0.71308 3.063" />
    <parent
      link="omniwheel4" />
    <child
      link="wheel48" />
    <axis
      xyz="1 0 0" />
  </joint>
  <link
    name="wheel49">
    <inertial>
      <origin
        xyz="7.1936E-06 3.4969E-06 6.6132E-06"
        rpy="0 0 0" />
      <mass
        value="0.0023" />
      <inertia
        ixx="2.1874E-07"
        ixy="5.957E-16"
        ixz="-6.4137E-16"
        iyy="2.4987E-07"
        iyz="2.9174E-18"
        izz="2.4987E-07" />
    </inertial>
    <visual>
      <origin
        xyz="0 0 0"
        rpy="0 0 0" />
      <geometry>
        <mesh
          filename="package://ballbot 3.0/meshes/wheel49.STL" />
      </geometry>
      <material
        name="">
        <color
          rgba="0.79216 0.81961 0.93333 1" />
      </material>
    </visual>
    <collision>
      <origin
        xyz="0 0 0"
        rpy="0 0 0" />
      <geometry>
        <mesh
          filename="package://ballbot 3.0/meshes/wheel49.STL" />
      </geometry>
    </collision>
  </link>
  <joint
    name="wheel49"
    type="continuous">
    <origin
      xyz="-0.0031507 -0.0080883 0.040222"
      rpy="-0.7391 0.014982 3.055" />
    <parent
      link="omniwheel4" />
    <child
      link="wheel49" />
    <axis
      xyz="-1 0 0" />
  </joint>
  <link
    name="wheel410">
    <inertial>
      <origin
        xyz="7.2147E-06 7.0627E-06 2.4072E-06"
        rpy="0 0 0" />
      <mass
        value="0.0023" />
      <inertia
        ixx="2.1874E-07"
        ixy="2.0029E-23"
        ixz="-1.0206E-15"
        iyy="2.4987E-07"
        iyz="2.595E-24"
        izz="2.4987E-07" />
    </inertial>
    <visual>
      <origin
        xyz="0 0 0"
        rpy="0 0 0" />
      <geometry>
        <mesh
          filename="package://ballbot 3.0/meshes/wheel410.STL" />
      </geometry>
      <material
        name="">
        <color
          rgba="0.79216 0.81961 0.93333 1" />
      </material>
    </visual>
    <collision>
      <origin
        xyz="0 0 0"
        rpy="0 0 0" />
      <geometry>
        <mesh
          filename="package://ballbot 3.0/meshes/wheel410.STL" />
      </geometry>
    </collision>
  </link>
  <joint
    name="wheel410"
    type="continuous">
    <origin
      xyz="-0.0042527 -0.030625 -0.039565"
      rpy="0.0093936 0.006392 3.0549" />
    <parent
      link="omniwheel4" />
    <child
      link="wheel410" />
    <axis
      xyz="1 0 0" />
  </joint>
  <link
    name="wheel411">
    <inertial>
      <origin
        xyz="4.0676E-06 7.0627E-06 6.2364E-06"
        rpy="0 0 0" />
      <mass
        value="0.0023" />
      <inertia
        ixx="2.1874E-07"
        ixy="-6.0908E-22"
        ixz="6.1003E-16"
        iyy="2.4987E-07"
        iyz="-1.4272E-23"
        izz="2.4987E-07" />
    </inertial>
    <visual>
      <origin
        xyz="0 0 0"
        rpy="0 0 0" />
      <geometry>
        <mesh
          filename="package://ballbot 3.0/meshes/wheel411.STL" />
      </geometry>
      <material
        name="">
        <color
          rgba="0.79216 0.81961 0.93333 1" />
      </material>
    </visual>
    <collision>
      <origin
        xyz="0 0 0"
        rpy="0 0 0" />
      <geometry>
        <mesh
          filename="package://ballbot 3.0/meshes/wheel411.STL" />
      </geometry>
    </collision>
  </link>
  <joint
    name="wheel411"
    type="continuous">
    <origin
      xyz="0.02131 -0.032759 -0.030043"
      rpy="0.012328 0.70449 3.0628" />
    <parent
      link="omniwheel4" />
    <child
      link="wheel411" />
    <axis
      xyz="1 0 0" />
  </joint>
  <link
    name="wheel412">
    <inertial>
      <origin
        xyz="-8.0329E-07 7.0627E-06 7.1477E-06"
        rpy="0 0 0" />
      <mass
        value="0.0023" />
      <inertia
        ixx="2.1874E-07"
        ixy="-1.6456E-22"
        ixz="6.1283E-15"
        iyy="2.4987E-07"
        iyz="4.9378E-24"
        izz="2.4987E-07" />
    </inertial>
    <visual>
      <origin
        xyz="0 0 0"
        rpy="0 0 0" />
      <geometry>
        <mesh
          filename="package://ballbot 3.0/meshes/wheel412.STL" />
      </geometry>
      <material
        name="">
        <color
          rgba="0.79216 0.81961 0.93333 1" />
      </material>
    </visual>
    <collision>
      <origin
        xyz="0 0 0"
        rpy="0 0 0" />
      <geometry>
        <mesh
          filename="package://ballbot 3.0/meshes/wheel412.STL" />
      </geometry>
    </collision>
  </link>
  <joint
    name="wheel412"
    type="continuous">
    <origin
      xyz="0.034807 -0.033708 -0.0062609"
      rpy="0.056073 1.4024 3.1101" />
    <parent
      link="omniwheel4" />
    <child
      link="wheel412" />
    <axis
      xyz="1 0 0" />
  </joint>
  <link
    name="wheel413">
    <inertial>
      <origin
        xyz="-5.1195E-06 7.0627E-06 4.7147E-06"
        rpy="0 0 0" />
      <mass
        value="0.0023" />
      <inertia
        ixx="2.1874E-07"
        ixy="3.4015E-22"
        ixz="1.3239E-14"
        iyy="2.4987E-07"
        iyz="5.1775E-24"
        izz="2.4987E-07" />
    </inertial>
    <visual>
      <origin
        xyz="0 0 0"
        rpy="0 0 0" />
      <geometry>
        <mesh
          filename="package://ballbot 3.0/meshes/wheel413.STL" />
      </geometry>
      <material
        name="">
        <color
          rgba="0.79216 0.81961 0.93333 1" />
      </material>
    </visual>
    <collision>
      <origin
        xyz="0 0 0"
        rpy="0 0 0" />
      <geometry>
        <mesh
          filename="package://ballbot 3.0/meshes/wheel413.STL" />
      </geometry>
    </collision>
  </link>
  <joint
    name="wheel413"
    type="continuous">
    <origin
      xyz="0.029924 -0.03303 0.020653"
      rpy="3.123 1.0407 -0.10279" />
    <parent
      link="omniwheel4" />
    <child
      link="wheel413" />
    <axis
      xyz="1 0 0" />
  </joint>
  <link
    name="wheel414">
    <inertial>
      <origin
        xyz="-6.8651E-06 7.0627E-06 7.5102E-08"
        rpy="0 0 0" />
      <mass
        value="0.0023" />
      <inertia
        ixx="2.1874E-07"
        ixy="7.7346E-23"
        ixz="1.7559E-15"
        iyy="2.4987E-07"
        iyz="-5.3396E-24"
        izz="2.4987E-07" />
    </inertial>
    <visual>
      <origin
        xyz="0 0 0"
        rpy="0 0 0" />
      <geometry>
        <mesh
          filename="package://ballbot 3.0/meshes/wheel414.STL" />
      </geometry>
      <material
        name="">
        <color
          rgba="0.79216 0.81961 0.93333 1" />
      </material>
    </visual>
    <collision>
      <origin
        xyz="0 0 0"
        rpy="0 0 0" />
      <geometry>
        <mesh
          filename="package://ballbot 3.0/meshes/wheel414.STL" />
      </geometry>
    </collision>
  </link>
  <joint
    name="wheel414"
    type="continuous">
    <origin
      xyz="0.0089455 -0.031041 0.038106"
      rpy="3.1316 0.34266 -0.090112" />
    <parent
      link="omniwheel4" />
    <child
      link="wheel414" />
    <axis
      xyz="1 0 0" />
  </joint>
  <link
    name="wheel415">
    <inertial>
      <origin
        xyz="-5.2144E-06 7.0627E-06 -4.599E-06"
        rpy="0 0 0" />
      <mass
        value="0.0023" />
      <inertia
        ixx="2.1874E-07"
        ixy="1.5335E-24"
        ixz="3.195E-15"
        iyy="2.4987E-07"
        iyz="-3.5907E-25"
        izz="2.4987E-07" />
    </inertial>
    <visual>
      <origin
        xyz="0 0 0"
        rpy="0 0 0" />
      <geometry>
        <mesh
          filename="package://ballbot 3.0/meshes/wheel415.STL" />
      </geometry>
      <material
        name="">
        <color
          rgba="0.79216 0.81961 0.93333 1" />
      </material>
    </visual>
    <collision>
      <origin
        xyz="0 0 0"
        rpy="0 0 0" />
      <geometry>
        <mesh
          filename="package://ballbot 3.0/meshes/wheel415.STL" />
      </geometry>
    </collision>
  </link>
  <joint
    name="wheel415"
    type="continuous">
    <origin
      xyz="-0.018313 -0.028671 0.037931"
      rpy="3.1316 -0.35544 -0.083274" />
    <parent
      link="omniwheel4" />
    <child
      link="wheel415" />
    <axis
      xyz="1 0 0" />
  </joint>
  <link
    name="wheel416">
    <inertial>
      <origin
        xyz="-9.5204E-07 7.0627E-06 -7.1202E-06"
        rpy="0 0 0" />
      <mass
        value="0.0023" />
      <inertia
        ixx="2.1874E-07"
        ixy="2.6461E-22"
        ixz="2.6543E-14"
        iyy="2.4987E-07"
        iyz="-2.9563E-24"
        izz="2.4987E-07" />
    </inertial>
    <visual>
      <origin
        xyz="0 0 0"
        rpy="0 0 0" />
      <geometry>
        <mesh
          filename="package://ballbot 3.0/meshes/wheel416.STL" />
      </geometry>
      <material
        name="">
        <color
          rgba="0.79216 0.81961 0.93333 1" />
      </material>
    </visual>
    <collision>
      <origin
        xyz="0 0 0"
        rpy="0 0 0" />
      <geometry>
        <mesh
          filename="package://ballbot 3.0/meshes/wheel416.STL" />
      </geometry>
    </collision>
  </link>
  <joint
    name="wheel416"
    type="continuous">
    <origin
      xyz="-0.039096 -0.027031 0.02021"
      rpy="3.1226 -1.0535 -0.07025" />
    <parent
      link="omniwheel4" />
    <child
      link="wheel416" />
    <axis
      xyz="1 0 0" />
  </joint>
  <link
    name="wheel417">
    <inertial>
      <origin
        xyz="3.9387E-06 7.0627E-06 -6.3103E-06"
        rpy="0 0 0" />
      <mass
        value="0.0023" />
      <inertia
        ixx="2.1874E-07"
        ixy="-5.6344E-23"
        ixz="2.2778E-14"
        iyy="2.4987E-07"
        iyz="-3.4354E-23"
        izz="2.4987E-07" />
    </inertial>
    <visual>
      <origin
        xyz="0 0 0"
        rpy="0 0 0" />
      <geometry>
        <mesh
          filename="package://ballbot 3.0/meshes/wheel417.STL" />
      </geometry>
      <material
        name="">
        <color
          rgba="0.79216 0.81961 0.93333 1" />
      </material>
    </visual>
    <collision>
      <origin
        xyz="0 0 0"
        rpy="0 0 0" />
      <geometry>
        <mesh
          filename="package://ballbot 3.0/meshes/wheel417.STL" />
      </geometry>
    </collision>
  </link>
  <joint
    name="wheel417"
    type="continuous">
    <origin
      xyz="-0.04368 -0.026886 -0.0067645"
      rpy="0.052157 -1.3896 3.0035" />
    <parent
      link="omniwheel4" />
    <child
      link="wheel417" />
    <axis
      xyz="1 0 0" />
  </joint>
  <link
    name="wheel418">
    <inertial>
      <origin
        xyz="7.1606E-06 7.0627E-06 -2.5482E-06"
        rpy="0 0 0" />
      <mass
        value="0.0023" />
      <inertia
        ixx="2.1874E-07"
        ixy="2.5465E-22"
        ixz="9.3027E-16"
        iyy="2.4987E-07"
        iyz="-2.7941E-23"
        izz="2.4987E-07" />
    </inertial>
    <visual>
      <origin
        xyz="0 0 0"
        rpy="0 0 0" />
      <geometry>
        <mesh
          filename="package://ballbot 3.0/meshes/wheel418.STL" />
      </geometry>
      <material
        name="">
        <color
          rgba="0.79216 0.81961 0.93333 1" />
      </material>
    </visual>
    <collision>
      <origin
        xyz="0 0 0"
        rpy="0 0 0" />
      <geometry>
        <mesh
          filename="package://ballbot 3.0/meshes/wheel418.STL" />
      </geometry>
    </collision>
  </link>
  <joint
    name="wheel418"
    type="continuous">
    <origin
      xyz="-0.029919 -0.028306 -0.030371"
      rpy="0.012197 -0.6917 3.0471" />
    <parent
      link="omniwheel4" />
    <child
      link="wheel418" />
    <axis
      xyz="1 0 0" />
  </joint>
  <link
    name="omniwheel1">
    <inertial>
      <origin
        xyz="-0.0018323 -0.017347 0.0028695"
        rpy="0 0 0" />
      <mass
        value="0.4" />
      <inertia
        ixx="5.3702E-05"
        ixy="9.3644E-07"
        ixz="-5.9471E-08"
        iyy="7.3422E-05"
        iyz="-1.4555E-06"
        izz="5.375E-05" />
    </inertial>
    <visual>
      <origin
        xyz="0 0 0"
        rpy="0 0 0" />
      <geometry>
        <mesh
          filename="package://ballbot 3.0/meshes/omniwheel1.STL" />
      </geometry>
      <material
        name="">
        <color
          rgba="1 1 1 1" />
      </material>
    </visual>
    <collision>
      <origin
        xyz="0 0 0"
        rpy="0 0 0" />
      <geometry>
        <mesh
          filename="package://ballbot 3.0/meshes/omniwheel1.STL" />
      </geometry>
    </collision>
  </link>
  <joint
    name="omniwheel1"
    type="continuous">
    <origin
      xyz="0.057368 -0.24133 -0.052798"
      rpy="0.95859 0.35957 3.0825" />
    <parent
      link="base_link" />
    <child
      link="omniwheel1" />
    <axis
      xyz="0 1 0" />
  </joint>
  <link
    name="wheel11">
    <inertial>
      <origin
        xyz="3.8113E-07 6.2405E-06 5.7962E-06"
        rpy="0 0 0" />
      <mass
        value="0.0023" />
      <inertia
        ixx="2.1874E-07"
        ixy="1.3618E-15"
        ixz="3.3533E-15"
        iyy="2.4987E-07"
        iyz="-3.4067E-17"
        izz="2.4987E-07" />
    </inertial>
    <visual>
      <origin
        xyz="0 0 0"
        rpy="0 0 0" />
      <geometry>
        <mesh
          filename="package://ballbot 3.0/meshes/wheel11.STL" />
      </geometry>
      <material
        name="">
        <color
          rgba="0.79216 0.81961 0.93333 1" />
      </material>
    </visual>
    <collision>
      <origin
        xyz="0 0 0"
        rpy="0 0 0" />
      <geometry>
        <mesh
          filename="package://ballbot 3.0/meshes/wheel11.STL" />
      </geometry>
    </collision>
  </link>
  <joint
    name="wheel11"
    type="continuous">
    <origin
      xyz="0.037549 -0.0097572 0.011185"
      rpy="-0.43376 -1.3329 2.7873" />
    <parent
      link="omniwheel1" />
    <child
      link="wheel11" />
    <axis
      xyz="1 0 0" />
  </joint>
  <link
    name="wheel12">
    <inertial>
      <origin
        xyz="3.8266E-07 6.2407E-06 5.7962E-06"
        rpy="0 0 0" />
      <mass
        value="0.0023" />
      <inertia
        ixx="2.1874E-07"
        ixy="4.9229E-15"
        ixz="2.8371E-15"
        iyy="2.4987E-07"
        iyz="-1.2206E-16"
        izz="2.4987E-07" />
    </inertial>
    <visual>
      <origin
        xyz="0 0 0"
        rpy="0 0 0" />
      <geometry>
        <mesh
          filename="package://ballbot 3.0/meshes/wheel12.STL" />
      </geometry>
      <material
        name="">
        <color
          rgba="0.79216 0.81961 0.93333 1" />
      </material>
    </visual>
    <collision>
      <origin
        xyz="0 0 0"
        rpy="0 0 0" />
      <geometry>
        <mesh
          filename="package://ballbot 3.0/meshes/wheel12.STL" />
      </geometry>
    </collision>
  </link>
  <joint
    name="wheel12"
    type="continuous">
    <origin
      xyz="0.034115 -0.011576 -0.0159"
      rpy="2.2335 -1.094 0.094214" />
    <parent
      link="omniwheel1" />
    <child
      link="wheel12" />
    <axis
      xyz="1 0 0" />
  </joint>
  <link
    name="wheel13">
    <inertial>
      <origin
        xyz="3.8062E-07 6.2407E-06 5.7963E-06"
        rpy="0 0 0" />
      <mass
        value="0.0023" />
      <inertia
        ixx="2.1874E-07"
        ixy="4.4536E-15"
        ixz="4.6171E-15"
        iyy="2.4987E-07"
        iyz="-1.4534E-16"
        izz="2.4987E-07" />
    </inertial>
    <visual>
      <origin
        xyz="0 0 0"
        rpy="0 0 0" />
      <geometry>
        <mesh
          filename="package://ballbot 3.0/meshes/wheel13.STL" />
      </geometry>
      <material
        name="">
        <color
          rgba="0.79216 0.81961 0.93333 1" />
      </material>
    </visual>
    <collision>
      <origin
        xyz="0 0 0"
        rpy="0 0 0" />
      <geometry>
        <mesh
          filename="package://ballbot 3.0/meshes/wheel13.STL" />
      </geometry>
    </collision>
  </link>
  <joint
    name="wheel13"
    type="continuous">
    <origin
      xyz="0.014055 -0.011977 -0.034504"
      rpy="2.3138 -0.39997 -0.016934" />
    <parent
      link="omniwheel1" />
    <child
      link="wheel13" />
    <axis
      xyz="1 0 0" />
  </joint>
  <link
    name="wheel14">
    <inertial>
      <origin
        xyz="3.7977E-07 6.2404E-06 5.7968E-06"
        rpy="0 0 0" />
      <mass
        value="0.0023" />
      <inertia
        ixx="2.1874E-07"
        ixy="-1.2993E-15"
        ixz="1.7947E-14"
        iyy="2.4987E-07"
        iyz="1.501E-16"
        izz="2.4987E-07" />
    </inertial>
    <visual>
      <origin
        xyz="0 0 0"
        rpy="0 0 0" />
      <geometry>
        <mesh
          filename="package://ballbot 3.0/meshes/wheel14.STL" />
      </geometry>
      <material
        name="">
        <color
          rgba="0.79216 0.81961 0.93333 1" />
      </material>
    </visual>
    <collision>
      <origin
        xyz="0 0 0"
        rpy="0 0 0" />
      <geometry>
        <mesh
          filename="package://ballbot 3.0/meshes/wheel14.STL" />
      </geometry>
    </collision>
  </link>
  <joint
    name="wheel14"
    type="continuous">
    <origin
      xyz="-0.013243 -0.010774 -0.035923"
      rpy="2.3168 0.29622 -0.070177" />
    <parent
      link="omniwheel1" />
    <child
      link="wheel14" />
    <axis
      xyz="1 0 0" />
  </joint>
  <link
    name="wheel15">
    <inertial>
      <origin
        xyz="3.8257E-07 6.2407E-06 5.796E-06"
        rpy="0 0 0" />
      <mass
        value="0.0023" />
      <inertia
        ixx="2.1874E-07"
        ixy="4.5111E-15"
        ixz="-1.2396E-15"
        iyy="2.4987E-07"
        iyz="4.8438E-17"
        izz="2.4987E-07" />
    </inertial>
    <visual>
      <origin
        xyz="0 0 0"
        rpy="0 0 0" />
      <geometry>
        <mesh
          filename="package://ballbot 3.0/meshes/wheel15.STL" />
      </geometry>
      <material
        name="">
        <color
          rgba="0.79216 0.81961 0.93333 1" />
      </material>
    </visual>
    <collision>
      <origin
        xyz="0 0 0"
        rpy="0 0 0" />
      <geometry>
        <mesh
          filename="package://ballbot 3.0/meshes/wheel15.STL" />
      </geometry>
    </collision>
  </link>
  <joint
    name="wheel15"
    type="continuous">
    <origin
      xyz="-0.035007 -0.0085285 -0.019493"
      rpy="2.2596 0.99107 -0.15978" />
    <parent
      link="omniwheel1" />
    <child
      link="wheel15" />
    <axis
      xyz="1 0 0" />
  </joint>
  <link
    name="wheel16">
    <inertial>
      <origin
        xyz="3.7925E-07 6.2408E-06 5.7963E-06"
        rpy="0 0 0" />
      <mass
        value="0.0023" />
      <inertia
        ixx="2.1874E-07"
        ixy="9.153E-15"
        ixz="6.373E-15"
        iyy="2.4987E-07"
        iyz="-3.5456E-16"
        izz="2.4987E-07" />
    </inertial>
    <visual>
      <origin
        xyz="0 0 0"
        rpy="0 0 0" />
      <geometry>
        <mesh
          filename="package://ballbot 3.0/meshes/wheel16.STL" />
      </geometry>
      <material
        name="">
        <color
          rgba="0.79216 0.81961 0.93333 1" />
      </material>
    </visual>
    <collision>
      <origin
        xyz="0 0 0"
        rpy="0 0 0" />
      <geometry>
        <mesh
          filename="package://ballbot 3.0/meshes/wheel16.STL" />
      </geometry>
    </collision>
  </link>
  <joint
    name="wheel16"
    type="continuous">
    <origin
      xyz="-0.041053 -0.006292 0.0070979"
      rpy="-0.20917 1.4283 -2.6546" />
    <parent
      link="omniwheel1" />
    <child
      link="wheel16" />
    <axis
      xyz="1 0 0" />
  </joint>
  <link
    name="wheel17">
    <inertial>
      <origin
        xyz="3.8173E-07 6.2404E-06 5.7967E-06"
        rpy="0 0 0" />
      <mass
        value="0.0023" />
      <inertia
        ixx="2.1874E-07"
        ixy="-1.5362E-15"
        ixz="1.271E-14"
        iyy="2.4987E-07"
        iyz="1.5529E-16"
        izz="2.4987E-07" />
    </inertial>
    <visual>
      <origin
        xyz="0 0 0"
        rpy="0 0 0" />
      <geometry>
        <mesh
          filename="package://ballbot 3.0/meshes/wheel17.STL" />
      </geometry>
      <material
        name="">
        <color
          rgba="0.79216 0.81961 0.93333 1" />
      </material>
    </visual>
    <collision>
      <origin
        xyz="0 0 0"
        rpy="0 0 0" />
      <geometry>
        <mesh
          filename="package://ballbot 3.0/meshes/wheel17.STL" />
      </geometry>
    </collision>
  </link>
  <joint
    name="wheel17"
    type="continuous">
    <origin
      xyz="-0.028553 -0.0051108 0.031408"
      rpy="-0.64886 0.74769 -3.1216" />
    <parent
      link="omniwheel1" />
    <child
      link="wheel17" />
    <axis
      xyz="1 0 0" />
  </joint>
  <link
    name="wheel18">
    <inertial>
      <origin
        xyz="3.8129E-07 6.2409E-06 5.7965E-06"
        rpy="0 0 0" />
      <mass
        value="0.0023" />
      <inertia
        ixx="2.1874E-07"
        ixy="9.5762E-15"
        ixz="9.0723E-15"
        iyy="2.4987E-07"
        iyz="-6.5958E-16"
        izz="2.4987E-07" />
    </inertial>
    <visual>
      <origin
        xyz="0 0 0"
        rpy="0 0 0" />
      <geometry>
        <mesh
          filename="package://ballbot 3.0/meshes/wheel18.STL" />
      </geometry>
      <material
        name="">
        <color
          rgba="0.79216 0.81961 0.93333 1" />
      </material>
    </visual>
    <collision>
      <origin
        xyz="0 0 0"
        rpy="0 0 0" />
      <geometry>
        <mesh
          filename="package://ballbot 3.0/meshes/wheel18.STL" />
      </geometry>
    </collision>
  </link>
  <joint
    name="wheel18"
    type="continuous">
    <origin
      xyz="-0.0033544 -0.0055375 0.042063"
      rpy="-0.67539 0.051897 3.0975" />
    <parent
      link="omniwheel1" />
    <child
      link="wheel18" />
    <axis
      xyz="1 0 0" />
  </joint>
  <link
    name="wheel19">
    <inertial>
      <origin
        xyz="3.7826E-07 6.2406E-06 5.7963E-06"
        rpy="0 0 0" />
      <mass
        value="0.0023" />
      <inertia
        ixx="2.1874E-07"
        ixy="2.5409E-15"
        ixz="5.2041E-15"
        iyy="2.4987E-07"
        iyz="-7.1881E-17"
        izz="2.4987E-07" />
    </inertial>
    <visual>
      <origin
        xyz="0 0 0"
        rpy="0 0 0" />
      <geometry>
        <mesh
          filename="package://ballbot 3.0/meshes/wheel19.STL" />
      </geometry>
      <material
        name="">
        <color
          rgba="0.79216 0.81961 0.93333 1" />
      </material>
    </visual>
    <collision>
      <origin
        xyz="0 0 0"
        rpy="0 0 0" />
      <geometry>
        <mesh
          filename="package://ballbot 3.0/meshes/wheel19.STL" />
      </geometry>
    </collision>
  </link>
  <joint
    name="wheel19"
    type="continuous">
    <origin
      xyz="0.022751 -0.0073725 0.034076"
      rpy="-0.65715 -0.64409 3.0388" />
    <parent
      link="omniwheel1" />
    <child
      link="wheel19" />
    <axis
      xyz="1 0 0" />
  </joint>
  <link
    name="wheel110">
    <inertial>
      <origin
        xyz="3.8066E-07 8.5167E-06 -1.5126E-10"
        rpy="0 0 0" />
      <mass
        value="0.0023" />
      <inertia
        ixx="2.1874E-07"
        ixy="-4.4968E-15"
        ixz="-3.4222E-15"
        iyy="2.4987E-07"
        iyz="-1.0924E-16"
        izz="2.4987E-07" />
    </inertial>
    <visual>
      <origin
        xyz="0 0 0"
        rpy="0 0 0" />
      <geometry>
        <mesh
          filename="package://ballbot 3.0/meshes/wheel110.STL" />
      </geometry>
      <material
        name="">
        <color
          rgba="0.79216 0.81961 0.93333 1" />
      </material>
    </visual>
    <collision>
      <origin
        xyz="0 0 0"
        rpy="0 0 0" />
      <geometry>
        <mesh
          filename="package://ballbot 3.0/meshes/wheel110.STL" />
      </geometry>
    </collision>
  </link>
  <joint
    name="wheel110"
    type="continuous">
    <origin
      xyz="-0.026895 -0.031408 -0.027832"
      rpy="0.091935 -0.65264 3.0378" />
    <parent
      link="omniwheel1" />
    <child
      link="wheel110" />
    <axis
      xyz="1 0 0" />
  </joint>
  <link
    name="wheel111">
    <inertial>
      <origin
        xyz="3.8037E-07 8.5163E-06 6.6884E-12"
        rpy="0 0 0" />
      <mass
        value="0.0023" />
      <inertia
        ixx="2.1874E-07"
        ixy="-1.3733E-14"
        ixz="1.5434E-16"
        iyy="2.4987E-07"
        iyz="1.4577E-17"
        izz="2.4987E-07" />
    </inertial>
    <visual>
      <origin
        xyz="0 0 0"
        rpy="0 0 0" />
      <geometry>
        <mesh
          filename="package://ballbot 3.0/meshes/wheel111.STL" />
      </geometry>
      <material
        name="">
        <color
          rgba="0.79216 0.81961 0.93333 1" />
      </material>
    </visual>
    <collision>
      <origin
        xyz="0 0 0"
        rpy="0 0 0" />
      <geometry>
        <mesh
          filename="package://ballbot 3.0/meshes/wheel111.STL" />
      </geometry>
    </collision>
  </link>
  <joint
    name="wheel111"
    type="continuous">
    <origin
      xyz="-0.00085976 -0.033256 -0.036043"
      rpy="0.073071 0.043329 3.0969" />
    <parent
      link="omniwheel1" />
    <child
      link="wheel111" />
    <axis
      xyz="1 0 0" />
  </joint>
  <link
    name="wheel112">
    <inertial>
      <origin
        xyz="3.8164E-07 8.5171E-06 3.6262E-10"
        rpy="0 0 0" />
      <mass
        value="0.0023" />
      <inertia
        ixx="2.1874E-07"
        ixy="4.6501E-15"
        ixz="7.6881E-15"
        iyy="2.4987E-07"
        iyz="-2.8157E-16"
        izz="2.4987E-07" />
    </inertial>
    <visual>
      <origin
        xyz="0 0 0"
        rpy="0 0 0" />
      <geometry>
        <mesh
          filename="package://ballbot 3.0/meshes/wheel112.STL" />
      </geometry>
      <material
        name="">
        <color
          rgba="0.79216 0.81961 0.93333 1" />
      </material>
    </visual>
    <collision>
      <origin
        xyz="0 0 0"
        rpy="0 0 0" />
      <geometry>
        <mesh
          filename="package://ballbot 3.0/meshes/wheel112.STL" />
      </geometry>
    </collision>
  </link>
  <joint
    name="wheel112"
    type="continuous">
    <origin
      xyz="0.024429 -0.033703 -0.025605"
      rpy="0.098852 0.73914 -3.1227" />
    <parent
      link="omniwheel1" />
    <child
      link="wheel112" />
    <axis
      xyz="1 0 0" />
  </joint>
  <link
    name="wheel113">
    <inertial>
      <origin
        xyz="3.8003E-07 8.5169E-06 -1.1558E-10"
        rpy="0 0 0" />
      <mass
        value="0.0023" />
      <inertia
        ixx="2.1874E-07"
        ixy="-5.9433E-16"
        ixz="-2.7289E-15"
        iyy="2.4987E-07"
        iyz="-1.0751E-17"
        izz="2.4987E-07" />
    </inertial>
    <visual>
      <origin
        xyz="0 0 0"
        rpy="0 0 0" />
      <geometry>
        <mesh
          filename="package://ballbot 3.0/meshes/wheel113.STL" />
      </geometry>
      <material
        name="">
        <color
          rgba="0.79216 0.81961 0.93333 1" />
      </material>
    </visual>
    <collision>
      <origin
        xyz="0 0 0"
        rpy="0 0 0" />
      <geometry>
        <mesh
          filename="package://ballbot 3.0/meshes/wheel113.STL" />
      </geometry>
    </collision>
  </link>
  <joint
    name="wheel113"
    type="continuous">
    <origin
      xyz="0.037138 -0.032539 -0.0014016"
      rpy="0.5101 1.4209 -2.6841" />
    <parent
      link="omniwheel1" />
    <child
      link="wheel113" />
    <axis
      xyz="1 0 0" />
  </joint>
  <link
    name="wheel114">
    <inertial>
      <origin
        xyz="3.8221E-07 8.5168E-06 -1.6368E-10"
        rpy="0 0 0" />
      <mass
        value="0.0023" />
      <inertia
        ixx="2.1874E-07"
        ixy="-1.2471E-15"
        ixz="-3.3443E-15"
        iyy="2.4987E-07"
        iyz="-3.4839E-17"
        izz="2.4987E-07" />
    </inertial>
    <visual>
      <origin
        xyz="0 0 0"
        rpy="0 0 0" />
      <geometry>
        <mesh
          filename="package://ballbot 3.0/meshes/wheel114.STL" />
      </geometry>
      <material
        name="">
        <color
          rgba="0.79216 0.81961 0.93333 1" />
      </material>
    </visual>
    <collision>
      <origin
        xyz="0 0 0"
        rpy="0 0 0" />
      <geometry>
        <mesh
          filename="package://ballbot 3.0/meshes/wheel114.STL" />
      </geometry>
    </collision>
  </link>
  <joint
    name="wheel114"
    type="continuous">
    <origin
      xyz="0.03132 -0.03031 0.025241"
      rpy="3.0063 0.99958 -0.1619" />
    <parent
      link="omniwheel1" />
    <child
      link="wheel114" />
    <axis
      xyz="1 0 0" />
  </joint>
  <link
    name="wheel115">
    <inertial>
      <origin
        xyz="3.7974E-07 8.5172E-06 4.4913E-10"
        rpy="0 0 0" />
      <mass
        value="0.0023" />
      <inertia
        ixx="2.1874E-07"
        ixy="7.2802E-15"
        ixz="1.0816E-14"
        iyy="2.4987E-07"
        iyz="-5.056E-16"
        izz="2.4987E-07" />
    </inertial>
    <visual>
      <origin
        xyz="0 0 0"
        rpy="0 0 0" />
      <geometry>
        <mesh
          filename="package://ballbot 3.0/meshes/wheel115.STL" />
      </geometry>
      <material
        name="">
        <color
          rgba="0.79216 0.81961 0.93333 1" />
      </material>
    </visual>
    <collision>
      <origin
        xyz="0 0 0"
        rpy="0 0 0" />
      <geometry>
        <mesh
          filename="package://ballbot 3.0/meshes/wheel115.STL" />
      </geometry>
    </collision>
  </link>
  <joint
    name="wheel115"
    type="continuous">
    <origin
      xyz="0.0096991 -0.028058 0.041858"
      rpy="3.0651 0.30478 -0.070864" />
    <parent
      link="omniwheel1" />
    <child
      link="wheel115" />
    <axis
      xyz="1 0 0" />
  </joint>
  <link
    name="wheel116">
    <inertial>
      <origin
        xyz="3.8141E-07 8.5162E-06 1.2506E-10"
        rpy="0 0 0" />
      <mass
        value="0.0023" />
      <inertia
        ixx="2.1874E-07"
        ixy="-1.4873E-14"
        ixz="2.6926E-15"
        iyy="2.4987E-07"
        iyz="3.0779E-16"
        izz="2.4987E-07" />
    </inertial>
    <visual>
      <origin
        xyz="0 0 0"
        rpy="0 0 0" />
      <geometry>
        <mesh
          filename="package://ballbot 3.0/meshes/wheel116.STL" />
      </geometry>
      <material
        name="">
        <color
          rgba="0.79216 0.81961 0.93333 1" />
      </material>
    </visual>
    <collision>
      <origin
        xyz="0 0 0"
        rpy="0 0 0" />
      <geometry>
        <mesh
          filename="package://ballbot 3.0/meshes/wheel116.STL" />
      </geometry>
    </collision>
  </link>
  <joint
    name="wheel116"
    type="continuous">
    <origin
      xyz="-0.017609 -0.026837 0.040673"
      rpy="3.0626 -0.39141 -0.017669" />
    <parent
      link="omniwheel1" />
    <child
      link="wheel116" />
    <axis
      xyz="1 0 0" />
  </joint>
  <link
    name="wheel117">
    <inertial>
      <origin
        xyz="3.8052E-07 8.5164E-06 -1.6322E-10"
        rpy="0 0 0" />
      <mass
        value="0.0023" />
      <inertia
        ixx="2.1874E-07"
        ixy="-1.0938E-14"
        ixz="-3.7282E-15"
        iyy="2.4987E-07"
        iyz="-2.8507E-16"
        izz="2.4987E-07" />
    </inertial>
    <visual>
      <origin
        xyz="0 0 0"
        rpy="0 0 0" />
      <geometry>
        <mesh
          filename="package://ballbot 3.0/meshes/wheel117.STL" />
      </geometry>
      <material
        name="">
        <color
          rgba="0.79216 0.81961 0.93333 1" />
      </material>
    </visual>
    <collision>
      <origin
        xyz="0 0 0"
        rpy="0 0 0" />
      <geometry>
        <mesh
          filename="package://ballbot 3.0/meshes/wheel117.STL" />
      </geometry>
    </collision>
  </link>
  <joint
    name="wheel117"
    type="continuous">
    <origin
      xyz="-0.037827 -0.027218 0.02224"
      rpy="2.9846 -1.0856 0.091286" />
    <parent
      link="omniwheel1" />
    <child
      link="wheel117" />
    <axis
      xyz="1 0 0" />
  </joint>
  <link
    name="wheel118">
    <inertial>
      <origin
        xyz="3.8096E-07 8.5169E-06 2.3151E-11"
        rpy="0 0 0" />
      <mass
        value="0.0023" />
      <inertia
        ixx="2.1874E-07"
        ixy="6.3055E-16"
        ixz="5.1328E-16"
        iyy="2.4987E-07"
        iyz="-2.3732E-18"
        izz="2.4987E-07" />
    </inertial>
    <visual>
      <origin
        xyz="0 0 0"
        rpy="0 0 0" />
      <geometry>
        <mesh
          filename="package://ballbot 3.0/meshes/wheel118.STL" />
      </geometry>
      <material
        name="">
        <color
          rgba="0.79216 0.81961 0.93333 1" />
      </material>
    </visual>
    <collision>
      <origin
        xyz="0 0 0"
        rpy="0 0 0" />
      <geometry>
        <mesh
          filename="package://ballbot 3.0/meshes/wheel118.STL" />
      </geometry>
    </collision>
  </link>
  <joint
    name="wheel118"
    type="continuous">
    <origin
      xyz="-0.041495 -0.029023 -0.0048142"
      rpy="0.3261 -1.3411 2.7756" />
    <parent
      link="omniwheel1" />
    <child
      link="wheel118" />
    <axis
      xyz="1 0 0" />
  </joint>
  <link
    name="omniwheel5">
    <inertial>
      <origin
        xyz="-0.0031533 -0.016315 -0.00089375"
        rpy="0 0 0" />
      <mass
        value="0.4" />
      <inertia
        ixx="5.3777E-05"
        ixy="1.6576E-06"
        ixz="4.008E-08"
        iyy="7.3423E-05"
        iyz="4.9161E-07"
        izz="5.3674E-05" />
    </inertial>
    <visual>
      <origin
        xyz="0 0 0"
        rpy="0 0 0" />
      <geometry>
        <mesh
          filename="package://ballbot 3.0/meshes/omniwheel5.STL" />
      </geometry>
      <material
        name="">
        <color
          rgba="1 1 1 1" />
      </material>
    </visual>
    <collision>
      <origin
        xyz="0 0 0"
        rpy="0 0 0" />
      <geometry>
        <mesh
          filename="package://ballbot 3.0/meshes/omniwheel5.STL" />
      </geometry>
    </collision>
  </link>
  <joint
    name="omniwheel5"
    type="continuous">
    <origin
      xyz="0.057417 -0.43864 -0.052798"
      rpy="1.8108 0.66219 2.4732" />
    <parent
      link="base_link" />
    <child
      link="omniwheel5" />
    <axis
      xyz="0 1 0" />
  </joint>
  <link
    name="wheel51">
    <inertial>
      <origin
        xyz="3.8138E-07 3.8475E-11 9.4655E-11"
        rpy="0 0 0" />
      <mass
        value="0.0023" />
      <inertia
        ixx="2.1874E-07"
        ixy="8.299E-16"
        ixz="2.0417E-15"
        iyy="2.4987E-07"
        iyz="-1.2984E-17"
        izz="2.4987E-07" />
    </inertial>
    <visual>
      <origin
        xyz="0 0 0"
        rpy="0 0 0" />
      <geometry>
        <mesh
          filename="package://ballbot 3.0/meshes/wheel51.STL" />
      </geometry>
      <material
        name="">
        <color
          rgba="0.79216 0.81961 0.93333 1" />
      </material>
    </visual>
    <collision>
      <origin
        xyz="0 0 0"
        rpy="0 0 0" />
      <geometry>
        <mesh
          filename="package://ballbot 3.0/meshes/wheel51.STL" />
      </geometry>
    </collision>
  </link>
  <joint
    name="wheel51"
    type="continuous">
    <origin
      xyz="0.0049082 -0.0091398 0.038616"
      rpy="-0.77436 -0.1869 3.0629" />
    <parent
      link="omniwheel5" />
    <child
      link="wheel51" />
    <axis
      xyz="1 0 0" />
  </joint>
  <link
    name="wheel52">
    <inertial>
      <origin
        xyz="3.8163E-07 8.5901E-10 6.6989E-10"
        rpy="0 0 0" />
      <mass
        value="0.0023" />
      <inertia
        ixx="2.1874E-07"
        ixy="1.8223E-14"
        ixz="1.4211E-14"
        iyy="2.4987E-07"
        iyz="-2.0378E-15"
        izz="2.4987E-07" />
    </inertial>
    <visual>
      <origin
        xyz="0 0 0"
        rpy="0 0 0" />
      <geometry>
        <mesh
          filename="package://ballbot 3.0/meshes/wheel52.STL" />
      </geometry>
      <material
        name="">
        <color
          rgba="0.79216 0.81961 0.93333 1" />
      </material>
    </visual>
    <collision>
      <origin
        xyz="0 0 0"
        rpy="0 0 0" />
      <geometry>
        <mesh
          filename="package://ballbot 3.0/meshes/wheel52.STL" />
      </geometry>
    </collision>
  </link>
  <joint
    name="wheel52"
    type="continuous">
    <origin
      xyz="0.02838 -0.010748 0.024646"
      rpy="-0.78863 -0.8847 3.0892" />
    <parent
      link="omniwheel5" />
    <child
      link="wheel52" />
    <axis
      xyz="1 0 0" />
  </joint>
  <link
    name="wheel53">
    <inertial>
      <origin
        xyz="3.7947E-07 -8.3539E-11 -4.3441E-11"
        rpy="0 0 0" />
      <mass
        value="0.0023" />
      <inertia
        ixx="2.1874E-07"
        ixy="-2.0497E-15"
        ixz="-1.0658E-15"
        iyy="2.4987E-07"
        iyz="-1.3612E-17"
        izz="2.4987E-07" />
    </inertial>
    <visual>
      <origin
        xyz="0 0 0"
        rpy="0 0 0" />
      <geometry>
        <mesh
          filename="package://ballbot 3.0/meshes/wheel53.STL" />
      </geometry>
      <material
        name="">
        <color
          rgba="0.79216 0.81961 0.93333 1" />
      </material>
    </visual>
    <collision>
      <origin
        xyz="0 0 0"
        rpy="0 0 0" />
      <geometry>
        <mesh
          filename="package://ballbot 3.0/meshes/wheel53.STL" />
      </geometry>
    </collision>
  </link>
  <joint
    name="wheel53"
    type="continuous">
    <origin
      xyz="0.037441 -0.010847 -0.0011717"
      rpy="-2.774 -1.5425 -1.1994" />
    <parent
      link="omniwheel5" />
    <child
      link="wheel53" />
    <axis
      xyz="1 0 0" />
  </joint>
  <link
    name="wheel54">
    <inertial>
      <origin
        xyz="3.8026E-07 3.3097E-10 2.9031E-10"
        rpy="0 0 0" />
      <mass
        value="0.0023" />
      <inertia
        ixx="2.1874E-07"
        ixy="7.6936E-15"
        ixz="6.7484E-15"
        iyy="2.4987E-07"
        iyz="-3.5289E-16"
        izz="2.4987E-07" />
    </inertial>
    <visual>
      <origin
        xyz="0 0 0"
        rpy="0 0 0" />
      <geometry>
        <mesh
          filename="package://ballbot 3.0/meshes/wheel54.STL" />
      </geometry>
      <material
        name="">
        <color
          rgba="0.79216 0.81961 0.93333 1" />
      </material>
    </visual>
    <collision>
      <origin
        xyz="0 0 0"
        rpy="0 0 0" />
      <geometry>
        <mesh
          filename="package://ballbot 3.0/meshes/wheel54.STL" />
      </geometry>
    </collision>
  </link>
  <joint
    name="wheel54"
    type="continuous">
    <origin
      xyz="0.027852 -0.0093919 -0.026757"
      rpy="2.4321 -0.85986 -0.11302" />
    <parent
      link="omniwheel5" />
    <child
      link="wheel54" />
    <axis
      xyz="1 0 0" />
  </joint>
  <link
    name="wheel55">
    <inertial>
      <origin
        xyz="3.8256E-07 3.3033E-10 9.252E-11"
        rpy="0 0 0" />
      <mass
        value="0.0023" />
      <inertia
        ixx="2.1874E-07"
        ixy="6.5995E-15"
        ixz="1.8484E-15"
        iyy="2.4987E-07"
        iyz="-1.0558E-16"
        izz="2.4987E-07" />
    </inertial>
    <visual>
      <origin
        xyz="0 0 0"
        rpy="0 0 0" />
      <geometry>
        <mesh
          filename="package://ballbot 3.0/meshes/wheel55.STL" />
      </geometry>
      <material
        name="">
        <color
          rgba="0.79216 0.81961 0.93333 1" />
      </material>
    </visual>
    <collision>
      <origin
        xyz="0 0 0"
        rpy="0 0 0" />
      <geometry>
        <mesh
          filename="package://ballbot 3.0/meshes/wheel55.STL" />
      </geometry>
    </collision>
  </link>
  <joint
    name="wheel55"
    type="continuous">
    <origin
      xyz="0.0040992 -0.0070627 -0.040138"
      rpy="2.4189 -0.16205 -0.087648" />
    <parent
      link="omniwheel5" />
    <child
      link="wheel55" />
    <axis
      xyz="1 0 0" />
  </joint>
  <link
    name="wheel56">
    <inertial>
      <origin
        xyz="3.8079E-07 4.1038E-11 -1.0457E-10"
        rpy="0 0 0" />
      <mass
        value="0.0023" />
      <inertia
        ixx="2.1874E-07"
        ixy="9.2043E-16"
        ixz="-2.3454E-15"
        iyy="2.4987E-07"
        iyz="1.554E-17"
        izz="2.4987E-07" />
    </inertial>
    <visual>
      <origin
        xyz="0 0 0"
        rpy="0 0 0" />
      <geometry>
        <mesh
          filename="package://ballbot 3.0/meshes/wheel56.STL" />
      </geometry>
      <material
        name="">
        <color
          rgba="0.79216 0.81961 0.93333 1" />
      </material>
    </visual>
    <collision>
      <origin
        xyz="0 0 0"
        rpy="0 0 0" />
      <geometry>
        <mesh
          filename="package://ballbot 3.0/meshes/wheel56.STL" />
      </geometry>
    </collision>
  </link>
  <joint
    name="wheel56"
    type="continuous">
    <origin
      xyz="-0.022703 -0.0049495 -0.035053"
      rpy="2.4227 0.53584 -0.068393" />
    <parent
      link="omniwheel5" />
    <child
      link="wheel56" />
    <axis
      xyz="1 0 0" />
  </joint>
  <link
    name="wheel57">
    <inertial>
      <origin
        xyz="3.7971E-07 9.2441E-11 9.9295E-10"
        rpy="0 0 0" />
      <mass
        value="0.0023" />
      <inertia
        ixx="2.1874E-07"
        ixy="2.2314E-15"
        ixz="2.3968E-14"
        iyy="2.4987E-07"
        iyz="-3.4211E-16"
        izz="2.4987E-07" />
    </inertial>
    <visual>
      <origin
        xyz="0 0 0"
        rpy="0 0 0" />
      <geometry>
        <mesh
          filename="package://ballbot 3.0/meshes/wheel57.STL" />
      </geometry>
      <material
        name="">
        <color
          rgba="0.79216 0.81961 0.93333 1" />
      </material>
    </visual>
    <collision>
      <origin
        xyz="0 0 0"
        rpy="0 0 0" />
      <geometry>
        <mesh
          filename="package://ballbot 3.0/meshes/wheel57.STL" />
      </geometry>
    </collision>
  </link>
  <joint
    name="wheel57"
    type="continuous">
    <origin
      xyz="-0.040013 -0.0040411 -0.013883"
      rpy="2.4699 1.2332 -0.010988" />
    <parent
      link="omniwheel5" />
    <child
      link="wheel57" />
    <axis
      xyz="1 0 0" />
  </joint>
  <link
    name="wheel58">
    <inertial>
      <origin
        xyz="3.8226E-07 2.0464E-10 3.773E-10"
        rpy="0 0 0" />
      <mass
        value="0.0023" />
      <inertia
        ixx="2.1874E-07"
        ixy="4.1673E-15"
        ixz="7.6833E-15"
        iyy="2.4987E-07"
        iyz="-2.6887E-16"
        izz="2.4987E-07" />
    </inertial>
    <visual>
      <origin
        xyz="0 0 0"
        rpy="0 0 0" />
      <geometry>
        <mesh
          filename="package://ballbot 3.0/meshes/wheel58.STL" />
      </geometry>
      <material
        name="">
        <color
          rgba="0.79216 0.81961 0.93333 1" />
      </material>
    </visual>
    <collision>
      <origin
        xyz="0 0 0"
        rpy="0 0 0" />
      <geometry>
        <mesh
          filename="package://ballbot 3.0/meshes/wheel58.STL" />
      </geometry>
    </collision>
  </link>
  <joint
    name="wheel58"
    type="continuous">
    <origin
      xyz="-0.039732 -0.0047624 0.013468"
      rpy="-0.82026 1.2084 2.991" />
    <parent
      link="omniwheel5" />
    <child
      link="wheel58" />
    <axis
      xyz="1 0 0" />
  </joint>
  <link
    name="wheel59">
    <inertial>
      <origin
        xyz="3.7991E-07 2.4541E-11 -1.0326E-10"
        rpy="0 0 0" />
      <mass
        value="0.0023" />
      <inertia
        ixx="2.1874E-07"
        ixy="5.8419E-16"
        ixz="-2.4582E-15"
        iyy="2.4987E-07"
        iyz="9.3941E-18"
        izz="2.4987E-07" />
    </inertial>
    <visual>
      <origin
        xyz="0 0 0"
        rpy="0 0 0" />
      <geometry>
        <mesh
          filename="package://ballbot 3.0/meshes/wheel59.STL" />
      </geometry>
      <material
        name="">
        <color
          rgba="0.79216 0.81961 0.93333 1" />
      </material>
    </visual>
    <collision>
      <origin
        xyz="0 0 0"
        rpy="0 0 0" />
      <geometry>
        <mesh
          filename="package://ballbot 3.0/meshes/wheel59.STL" />
      </geometry>
    </collision>
  </link>
  <joint
    name="wheel59"
    type="continuous">
    <origin
      xyz="-0.021991 -0.0067761 0.034201"
      rpy="-0.77764 0.51099 3.0438" />
    <parent
      link="omniwheel5" />
    <child
      link="wheel59" />
    <axis
      xyz="1 0 0" />
  </joint>
  <link
    name="wheel510">
    <inertial>
      <origin
        xyz="3.7985E-07 -4.3249E-11 -8.0254E-11"
        rpy="0 0 0" />
      <mass
        value="0.0023" />
      <inertia
        ixx="2.1874E-07"
        ixy="-1.0338E-15"
        ixz="-1.9184E-15"
        iyy="2.4987E-07"
        iyz="-1.2887E-17"
        izz="2.4987E-07" />
    </inertial>
    <visual>
      <origin
        xyz="0 0 0"
        rpy="0 0 0" />
      <geometry>
        <mesh
          filename="package://ballbot 3.0/meshes/wheel510.STL" />
      </geometry>
      <material
        name="">
        <color
          rgba="0.79216 0.81961 0.93333 1" />
      </material>
    </visual>
    <collision>
      <origin
        xyz="0 0 0"
        rpy="0 0 0" />
      <geometry>
        <mesh
          filename="package://ballbot 3.0/meshes/wheel510.STL" />
      </geometry>
    </collision>
  </link>
  <joint
    name="wheel510"
    type="continuous">
    <origin
      xyz="0.01504 -0.029957 -0.036271"
      rpy="-0.029005 0.5024 3.0441" />
    <parent
      link="omniwheel5" />
    <child
      link="wheel510" />
    <axis
      xyz="1 0 0" />
  </joint>
  <link
    name="wheel511">
    <inertial>
      <origin
        xyz="3.8167E-07 2.3687E-10 4.6138E-11"
        rpy="0 0 0" />
      <mass
        value="0.0023" />
      <inertia
        ixx="2.1874E-07"
        ixy="5.0102E-15"
        ixz="9.759E-16"
        iyy="2.4987E-07"
        iyz="-3.8655E-17"
        izz="2.4987E-07" />
    </inertial>
    <visual>
      <origin
        xyz="0 0 0"
        rpy="0 0 0" />
      <geometry>
        <mesh
          filename="package://ballbot 3.0/meshes/wheel511.STL" />
      </geometry>
      <material
        name="">
        <color
          rgba="0.79216 0.81961 0.93333 1" />
      </material>
    </visual>
    <collision>
      <origin
        xyz="0 0 0"
        rpy="0 0 0" />
      <geometry>
        <mesh
          filename="package://ballbot 3.0/meshes/wheel511.STL" />
      </geometry>
    </collision>
  </link>
  <joint
    name="wheel511"
    type="continuous">
    <origin
      xyz="0.032958 -0.031982 -0.015692"
      rpy="-0.07018 1.1999 2.9927" />
    <parent
      link="omniwheel5" />
    <child
      link="wheel511" />
    <axis
      xyz="1 0 0" />
  </joint>
  <link
    name="wheel512">
    <inertial>
      <origin
        xyz="3.8004E-07 5.3287E-10 4.6578E-10"
        rpy="0 0 0" />
      <mass
        value="0.0023" />
      <inertia
        ixx="2.1874E-07"
        ixy="1.2579E-14"
        ixz="1.0995E-14"
        iyy="2.4987E-07"
        iyz="-9.1705E-16"
        izz="2.4987E-07" />
    </inertial>
    <visual>
      <origin
        xyz="0 0 0"
        rpy="0 0 0" />
      <geometry>
        <mesh
          filename="package://ballbot 3.0/meshes/wheel512.STL" />
      </geometry>
      <material
        name="">
        <color
          rgba="0.79216 0.81961 0.93333 1" />
      </material>
    </visual>
    <collision>
      <origin
        xyz="0 0 0"
        rpy="0 0 0" />
      <geometry>
        <mesh
          filename="package://ballbot 3.0/meshes/wheel512.STL" />
      </geometry>
    </collision>
  </link>
  <joint
    name="wheel512"
    type="continuous">
    <origin
      xyz="0.033473 -0.032723 0.011655"
      rpy="-3.0628 1.2418 -0.0089472" />
    <parent
      link="omniwheel5" />
    <child
      link="wheel512" />
    <axis
      xyz="1 0 0" />
  </joint>
  <link
    name="wheel513">
    <inertial>
      <origin
        xyz="3.8164E-07 -5.5496E-10 5.3086E-10"
        rpy="0 0 0" />
      <mass
        value="0.0023" />
      <inertia
        ixx="2.1874E-07"
        ixy="-1.1769E-14"
        ixz="1.1258E-14"
        iyy="2.4987E-07"
        iyz="1.0431E-15"
        izz="2.4987E-07" />
    </inertial>
    <visual>
      <origin
        xyz="0 0 0"
        rpy="0 0 0" />
      <geometry>
        <mesh
          filename="package://ballbot 3.0/meshes/wheel513.STL" />
      </geometry>
      <material
        name="">
        <color
          rgba="0.79216 0.81961 0.93333 1" />
      </material>
    </visual>
    <collision>
      <origin
        xyz="0 0 0"
        rpy="0 0 0" />
      <geometry>
        <mesh
          filename="package://ballbot 3.0/meshes/wheel513.STL" />
      </geometry>
    </collision>
  </link>
  <joint
    name="wheel513"
    type="continuous">
    <origin
      xyz="0.016344 -0.031833 0.032973"
      rpy="-3.1119 0.54443 -0.068096" />
    <parent
      link="omniwheel5" />
    <child
      link="wheel513" />
    <axis
      xyz="1 0 0" />
  </joint>
  <link
    name="wheel514">
    <inertial>
      <origin
        xyz="3.7993E-07 -3.5506E-11 1.6448E-11"
        rpy="0 0 0" />
      <mass
        value="0.0023" />
      <inertia
        ixx="2.1874E-07"
        ixy="-8.4421E-16"
        ixz="3.9108E-16"
        iyy="2.4987E-07"
        iyz="2.1639E-18"
        izz="2.4987E-07" />
    </inertial>
    <visual>
      <origin
        xyz="0 0 0"
        rpy="0 0 0" />
      <geometry>
        <mesh
          filename="package://ballbot 3.0/meshes/wheel514.STL" />
      </geometry>
      <material
        name="">
        <color
          rgba="0.79216 0.81961 0.93333 1" />
      </material>
    </visual>
    <collision>
      <origin
        xyz="0 0 0"
        rpy="0 0 0" />
      <geometry>
        <mesh
          filename="package://ballbot 3.0/meshes/wheel514.STL" />
      </geometry>
    </collision>
  </link>
  <joint
    name="wheel514"
    type="continuous">
    <origin
      xyz="-0.010414 -0.029729 0.038288"
      rpy="-3.1159 -0.15346 -0.087424" />
    <parent
      link="omniwheel5" />
    <child
      link="wheel514" />
    <axis
      xyz="1 0 0" />
  </joint>
  <link
    name="wheel515">
    <inertial>
      <origin
        xyz="3.8142E-07 3.617E-11 -2.5813E-10"
        rpy="0 0 0" />
      <mass
        value="0.0023" />
      <inertia
        ixx="2.1874E-07"
        ixy="7.7816E-16"
        ixz="-5.5534E-15"
        iyy="2.4987E-07"
        iyz="3.3251E-17"
        izz="2.4987E-07" />
    </inertial>
    <visual>
      <origin
        xyz="0 0 0"
        rpy="0 0 0" />
      <geometry>
        <mesh
          filename="package://ballbot 3.0/meshes/wheel515.STL" />
      </geometry>
      <material
        name="">
        <color
          rgba="0.79216 0.81961 0.93333 1" />
      </material>
    </visual>
    <collision>
      <origin
        xyz="0 0 0"
        rpy="0 0 0" />
      <geometry>
        <mesh
          filename="package://ballbot 3.0/meshes/wheel515.STL" />
      </geometry>
    </collision>
  </link>
  <joint
    name="wheel515"
    type="continuous">
    <origin
      xyz="-0.03428 -0.027396 0.025113"
      rpy="-3.103 -0.85127 -0.11251" />
    <parent
      link="omniwheel5" />
    <child
      link="wheel515" />
    <axis
      xyz="1 0 0" />
  </joint>
  <link
    name="wheel516">
    <inertial>
      <origin
        xyz="3.7994E-07 -9.6158E-11 -1.46E-11"
        rpy="0 0 0" />
      <mass
        value="0.0023" />
      <inertia
        ixx="2.1874E-07"
        ixy="-2.2852E-15"
        ixz="-3.4696E-16"
        iyy="2.4987E-07"
        iyz="-5.2008E-18"
        izz="2.4987E-07" />
    </inertial>
    <visual>
      <origin
        xyz="0 0 0"
        rpy="0 0 0" />
      <geometry>
        <mesh
          filename="package://ballbot 3.0/meshes/wheel516.STL" />
      </geometry>
      <material
        name="">
        <color
          rgba="0.79216 0.81961 0.93333 1" />
      </material>
    </visual>
    <collision>
      <origin
        xyz="0 0 0"
        rpy="0 0 0" />
      <geometry>
        <mesh
          filename="package://ballbot 3.0/meshes/wheel516.STL" />
      </geometry>
    </collision>
  </link>
  <joint
    name="wheel516"
    type="continuous">
    <origin
      xyz="-0.044089 -0.025925 -0.00038813"
      rpy="-2.2616 -1.5378 -0.96319" />
    <parent
      link="omniwheel5" />
    <child
      link="wheel516" />
    <axis
      xyz="1 0 0" />
  </joint>
  <link
    name="wheel517">
    <inertial>
      <origin
        xyz="3.8084E-07 6.2586E-12 -1.8691E-12"
        rpy="0 0 0" />
      <mass
        value="0.0023" />
      <inertia
        ixx="2.1874E-07"
        ixy="1.3991E-16"
        ixz="-4.1783E-17"
        iyy="2.4987E-07"
        iyz="4.2285E-20"
        izz="2.4987E-07" />
    </inertial>
    <visual>
      <origin
        xyz="0 0 0"
        rpy="0 0 0" />
      <geometry>
        <mesh
          filename="package://ballbot 3.0/meshes/wheel517.STL" />
      </geometry>
      <material
        name="">
        <color
          rgba="0.79216 0.81961 0.93333 1" />
      </material>
    </visual>
    <collision>
      <origin
        xyz="0 0 0"
        rpy="0 0 0" />
      <geometry>
        <mesh
          filename="package://ballbot 3.0/meshes/wheel517.STL" />
      </geometry>
    </collision>
  </link>
  <joint
    name="wheel517"
    type="continuous">
    <origin
      xyz="-0.035249 -0.026004 -0.026282"
      rpy="-0.040559 -0.89328 3.0897" />
    <parent
      link="omniwheel5" />
    <child
      link="wheel517" />
    <axis
      xyz="1 0 0" />
  </joint>
  <link
    name="wheel518">
    <inertial>
      <origin
        xyz="3.8195E-07 1.4231E-10 -5.2643E-11"
        rpy="0 0 0" />
      <mass
        value="0.0023" />
      <inertia
        ixx="2.1874E-07"
        ixy="2.9567E-15"
        ixz="-1.0937E-15"
        iyy="2.4987E-07"
        iyz="2.6305E-17"
        izz="2.4987E-07" />
    </inertial>
    <visual>
      <origin
        xyz="0 0 0"
        rpy="0 0 0" />
      <geometry>
        <mesh
          filename="package://ballbot 3.0/meshes/wheel518.STL" />
      </geometry>
      <material
        name="">
        <color
          rgba="0.79216 0.81961 0.93333 1" />
      </material>
    </visual>
    <collision>
      <origin
        xyz="0 0 0"
        rpy="0 0 0" />
      <geometry>
        <mesh
          filename="package://ballbot 3.0/meshes/wheel518.STL" />
      </geometry>
    </collision>
  </link>
  <joint
    name="wheel518"
    type="continuous">
    <origin
      xyz="-0.011897 -0.027596 -0.040454"
      rpy="-0.025914 -0.19549 3.0631" />
    <parent
      link="omniwheel5" />
    <child
      link="wheel518" />
    <axis
      xyz="1 0 0" />
  </joint>
</robot>